1607156728659	Sync.SyncScheduler	DEBUG	Next sync in 3600000 ms. (why=schedule)
1607156728791	Sync.RemoteTabs	INFO	Generating tab list with filter
1607156728792	Sync.RemoteTabs	INFO	Final tab list has 0 clients with 0 tabs.
1607157890953	Sync.SyncScheduler	DEBUG	Going to sleep, doing a quick sync.
1607157890954	Sync.Service	DEBUG	User-Agent: Firefox/83.0 (Windows NT 10.0; Win64; x64) FxSync/1.85.0.20201112153044.desktop
1607157890954	Sync.Service	INFO	Starting sync at 2020-12-05 14:14:50 in browser session b6wfxJ7X62ws
1607157890954	Sync.SyncScheduler	DEBUG	Clearing sync triggers and the global score.
1607157890958	Sync.Status	INFO	Resetting Status.
1607157890958	Sync.Status	DEBUG	Status.service: success.status_ok => success.status_ok
1607157890959	FirefoxAccounts	DEBUG	FxAccountsProfileClient: Requested profile
1607157890959	FirefoxAccounts	DEBUG	getOAuthToken enter
1607157890961	FirefoxAccounts	TRACE	getCachedToken returning cached token
1607157890961	FirefoxAccounts	DEBUG	getOAuthToken returning a cached token
1607157890962	Services.Common.RESTRequest	DEBUG	GET request to https://profile.accounts.firefox.com/v1/profile
1607160073927	Sync.SyncScheduler	DEBUG	Network link status changed to "down". Offline?: false
1607160073929	Sync.SyncScheduler	DEBUG	Clearing sync triggers and the global score.
1607160073939	Sync.SyncScheduler	DEBUG	Next sync in 3600000 ms. (why=schedule)
1607160074298	Sync.SyncScheduler	DEBUG	Network link status changed to "up". Offline?: false
1607160074298	Sync.SyncScheduler	DEBUG	Network link looks up. Syncing.
1607160074300	Sync.Service	DEBUG	User-Agent: Firefox/83.0 (Windows NT 10.0; Win64; x64) FxSync/1.85.0.20201112153044.desktop
1607160074300	Sync.Service	INFO	Starting sync at 2020-12-05 14:51:14 in browser session b6wfxJ7X62ws
1607160074300	Sync.Service	DEBUG	Exception calling anonymous function: LockException: Could not acquire lock. Label: "service.js: sync".(resource://services-sync/util.js:62:5) JS Stack trace: LockException@util.js:62:5
throwLockException@util.js:148:11
WrappedLock@util.js:162:15
_lockedSync@service.js:1370:6
sync/<@service.js:1334:18
WrappedCatch@util.js:133:27
sync@service.js:1335:7
1607160074300	Sync.Service	INFO	Cannot start sync: already syncing?
1607160074306	Sync.SyncScheduler	DEBUG	Network link status changed to "up". Offline?: false
1607160074306	Sync.SyncScheduler	DEBUG	Network link looks up. Syncing.
1607160074307	Sync.Service	DEBUG	User-Agent: Firefox/83.0 (Windows NT 10.0; Win64; x64) FxSync/1.85.0.20201112153044.desktop
1607160074307	Sync.Service	INFO	Starting sync at 2020-12-05 14:51:14 in browser session b6wfxJ7X62ws
1607160074308	Sync.Service	DEBUG	Exception calling anonymous function: LockException: Could not acquire lock. Label: "service.js: sync".(resource://services-sync/util.js:62:5) JS Stack trace: LockException@util.js:62:5
throwLockException@util.js:148:11
WrappedLock@util.js:162:15
_lockedSync@service.js:1370:6
sync/<@service.js:1334:18
WrappedCatch@util.js:133:27
sync@service.js:1335:7
1607160074308	Sync.Service	INFO	Cannot start sync: already syncing?
1607160076088	Sync.SyncScheduler	DEBUG	Woke from sleep.
1607160076579	Sync.SyncScheduler	DEBUG	Network link status changed to "changed". Offline?: false
1607160076596	Services.Common.RESTRequest	DEBUG	GET https://profile.accounts.firefox.com/v1/profile failed: 2152398862 - NS_ERROR_NET_TIMEOUT
1607160076617	FirefoxAccounts	ERROR	Background refresh of profile failed: {"name":"FxAccountsProfileClientError","code":null,"errno":998,"error":"NETWORK_ERROR","message":"[Exception... \"NS_ERROR_NET_TIMEOUT\"  nsresult: \"0x804b000e (NS_ERROR_NET_TIMEOUT)\"  location: \"JS frame :: resource://services-common/rest.js :: onStopRequest :: line 488\"  data: no]"}
1607160076620	Sync.Resource	WARN	GET request to https://sync-1-us-west1-g.sync.services.mozilla.com/1.5/174343456/info/collections failed: [Exception... "The connection has timed out"  nsresult: "0x804b000e (NS_ERROR_NET_TIMEOUT)"  location: "<unknown>"  data: no] No traceback available
1607160076620	Sync.Status	DEBUG	Status.sync: success.sync => error.login.reason.network
1607160076620	Sync.Status	DEBUG	Status.service: success.status_ok => error.sync.failed
1607160076621	Sync.ErrorHandler	ERROR	Sync encountered an error: [Exception... "The connection has timed out"  nsresult: "0x804b000e (NS_ERROR_NET_TIMEOUT)"  location: "<unknown>"  data: no] No traceback available
1607160076622	Sync.SyncScheduler	DEBUG	Next sync in 3600000 ms. (why=reschedule)
1607160076625	Sync.Service	DEBUG	Exception calling anonymous function: [Exception... "The connection has timed out"  nsresult: "0x804b000e (NS_ERROR_NET_TIMEOUT)"  location: "<unknown>"  data: no] No traceback available
